Traceback (most recent call last):
  File "/home/test/anaconda3/envs/FRL_test/lib/python3.10/site-packages/wandb/sdk/wandb_config.py", line 162, in __getattr__
    return self.__getitem__(key)
  File "/home/test/anaconda3/envs/FRL_test/lib/python3.10/site-packages/wandb/sdk/wandb_config.py", line 130, in __getitem__
    return self._items[key]
KeyError: 'mode'
The above exception was the direct cause of the following exception:
Traceback (most recent call last):
  File "/home/test/FRL/main.py", line 31, in <module>
    from FL_train import *
  File "/home/test/FRL/FL_train.py", line 22, in <module>
    import defense
  File "/home/test/FRL/defense.py", line 92, in <module>
    def FRL_fang(FLmodel, user_updates,round_users,n_attackers,val_loader,criterion,device,initial_scores,mode=wandb.config.mode):
  File "/home/test/anaconda3/envs/FRL_test/lib/python3.10/site-packages/wandb/sdk/wandb_config.py", line 164, in __getattr__
    raise AttributeError(
AttributeError: <class 'wandb.sdk.wandb_config.Config'> object has no attribute 'mode'