Traceback (most recent call last):
  File "/home/test/anaconda3/envs/FRL_test/lib/python3.10/site-packages/wandb/sdk/wandb_config.py", line 162, in __getattr__
    return self.__getitem__(key)
  File "/home/test/anaconda3/envs/FRL_test/lib/python3.10/site-packages/wandb/sdk/wandb_config.py", line 130, in __getitem__
    return self._items[key]
KeyError: 'lr'
The above exception was the direct cause of the following exception:
Traceback (most recent call last):
  File "/home/test/FRL/main.py", line 96, in <module>
    main()
  File "/home/test/FRL/main.py", line 81, in main
    My_attack(tr_loaders, te_loader)
  File "/home/test/FRL/FL_train.py", line 40, in My_attack
    lr = wandb.config.lr
  File "/home/test/anaconda3/envs/FRL_test/lib/python3.10/site-packages/wandb/sdk/wandb_config.py", line 164, in __getattr__
    raise AttributeError(
AttributeError: <class 'wandb.sdk.wandb_config.Config'> object has no attribute 'lr'