2024-06-03 12:54:51,212 INFO    Thread-9 (_run_job):390404 [wandb_setup.py:_flush():76] Current SDK version is 0.16.6
2024-06-03 12:54:51,212 INFO    Thread-9 (_run_job):390404 [wandb_setup.py:_flush():76] Configure stats pid to 390404
2024-06-03 12:54:51,212 INFO    Thread-9 (_run_job):390404 [wandb_setup.py:_flush():76] Loading settings from /home/test/.config/wandb/settings
2024-06-03 12:54:51,212 INFO    Thread-9 (_run_job):390404 [wandb_setup.py:_flush():76] Loading settings from /home/test/FRL/wandb/settings
2024-06-03 12:54:51,212 INFO    Thread-9 (_run_job):390404 [wandb_setup.py:_flush():76] Loading settings from environment variables: {'project': 'mnist-conv2-my-attack-cosine', 'entity': 'griffith', 'root_dir': '/home/test/FRL', 'run_id': '67ee5rd2', 'sweep_param_path': '/home/test/FRL/wandb/sweep-0vgdpsor/config-67ee5rd2.yaml', 'sweep_id': '0vgdpsor'}
2024-06-03 12:54:51,212 INFO    Thread-9 (_run_job):390404 [wandb_setup.py:_flush():76] Applying setup settings: {'_disable_service': False}
2024-06-03 12:54:51,212 INFO    Thread-9 (_run_job):390404 [wandb_setup.py:_flush():76] Inferring run settings from compute environment: {'program_relpath': 'main.py', 'program_abspath': '/home/test/FRL/main.py', 'program': '/home/test/FRL/main.py'}
2024-06-03 12:54:51,212 INFO    Thread-9 (_run_job):390404 [wandb_setup.py:_flush():76] Applying login settings: {}
2024-06-03 12:54:51,212 INFO    Thread-9 (_run_job):390404 [wandb_init.py:_log_setup():521] Logging user logs to /home/test/FRL/wandb/run-20240603_125451-67ee5rd2/logs/debug.log
2024-06-03 12:54:51,212 INFO    Thread-9 (_run_job):390404 [wandb_init.py:_log_setup():522] Logging internal logs to /home/test/FRL/wandb/run-20240603_125451-67ee5rd2/logs/debug-internal.log
2024-06-03 12:54:51,212 INFO    Thread-9 (_run_job):390404 [wandb_init.py:init():561] calling init triggers
2024-06-03 12:54:51,213 INFO    Thread-9 (_run_job):390404 [wandb_init.py:init():568] wandb.init called with sweep_config: {'iteration': 50, 'k': 0.1, 'lr': 0.001, 'm_r': 0, 'max_t': 2500, 'nep': 100, 'noise': 1, 'non_iid': 1, 'temp': 0.1}
config: {}
2024-06-03 12:54:51,213 INFO    Thread-9 (_run_job):390404 [wandb_init.py:init():606] wandb.init() called when a run is still active
2024-06-03 12:54:52,743 INFO    Thread-9 (_run_job):390404 [wandb_run.py:_finish():2064] finishing run griffith/mnist-conv2-my-attack-cosine/67ee5rd2
2024-06-03 12:54:52,743 INFO    Thread-9 (_run_job):390404 [wandb_run.py:_atexit_cleanup():2304] got exitcode: 1
2024-06-03 12:54:52,743 INFO    Thread-9 (_run_job):390404 [wandb_run.py:_restore():2287] restore
2024-06-03 12:54:52,743 INFO    Thread-9 (_run_job):390404 [wandb_run.py:_restore():2293] restore done
2024-06-03 12:54:56,469 INFO    Thread-9 (_run_job):390404 [wandb_run.py:_footer_history_summary_info():3936] rendering history
2024-06-03 12:54:56,469 INFO    Thread-9 (_run_job):390404 [wandb_run.py:_footer_history_summary_info():3968] rendering summary
2024-06-03 12:54:56,485 INFO    Thread-9 (_run_job):390404 [wandb_run.py:_footer_sync_info():3895] logging synced files
2024-06-03 12:54:56,511 ERROR   MainThread:390404 [pyagent.py:_run_jobs_from_queue():236] Run 67ee5rd2 errored:
Traceback (most recent call last):
  File "/home/test/anaconda3/envs/FRL_test/lib/python3.10/site-packages/wandb/sdk/wandb_config.py", line 162, in __getattr__
    return self.__getitem__(key)
  File "/home/test/anaconda3/envs/FRL_test/lib/python3.10/site-packages/wandb/sdk/wandb_config.py", line 130, in __getitem__
    return self._items[key]
KeyError: 'mode'

The above exception was the direct cause of the following exception:

Traceback (most recent call last):
  File "/home/test/anaconda3/envs/FRL_test/lib/python3.10/site-packages/wandb/agents/pyagent.py", line 308, in _run_job
    self._function()
  File "/home/test/FRL/main.py", line 115, in main
    FRL_train_defense_val(tr_loaders, te_loader,val_loader)
  File "/home/test/FRL/FL_train.py", line 604, in FRL_train_defense_val
    selected_user_updates=defense.FRL_fang(FLmodel, user_updates,len(round_users),len(round_malicious),val_loader,criterion, args.device,initial_scores,mode=wandb.config.mode)
  File "/home/test/anaconda3/envs/FRL_test/lib/python3.10/site-packages/wandb/sdk/wandb_config.py", line 164, in __getattr__
    raise AttributeError(
AttributeError: <class 'wandb.sdk.wandb_config.Config'> object has no attribute 'mode'

2024-06-03 12:54:56,511 ERROR   MainThread:390404 [pyagent.py:_run_jobs_from_queue():247] Detected 3 failed runs in the first 60 seconds, killing sweep.
