Traceback (most recent call last):
  File "/home/test/anaconda3/envs/FRL_test/lib/python3.10/site-packages/wandb/sdk/wandb_config.py", line 162, in __getattr__
    return self.__getitem__(key)
  File "/home/test/anaconda3/envs/FRL_test/lib/python3.10/site-packages/wandb/sdk/wandb_config.py", line 130, in __getitem__
    return self._items[key]
KeyError: 'non_iid'
The above exception was the direct cause of the following exception:
Traceback (most recent call last):
  File "/home/test/FRL/main.py", line 8, in <module>
    import data
  File "/home/test/FRL/data/__init__.py", line 26, in <module>
    from data.cifar10 import CIFAR10
  File "/home/test/FRL/data/cifar10.py", line 5, in <module>
    from data.Dirichlet_noniid import *
  File "/home/test/FRL/data/Dirichlet_noniid.py", line 18, in <module>
    def sample_dirichlet_train_data_train(train_dataset, no_participants, alpha=wandb.config.non_iid, force=False):
  File "/home/test/anaconda3/envs/FRL_test/lib/python3.10/site-packages/wandb/sdk/wandb_config.py", line 164, in __getattr__
    raise AttributeError(
AttributeError: <class 'wandb.sdk.wandb_config.Config'> object has no attribute 'non_iid'