Traceback (most recent call last):
  File "/home/test/anaconda3/envs/FRL_test/lib/python3.10/site-packages/wandb/sdk/wandb_config.py", line 162, in __getattr__
    return self.__getitem__(key)
  File "/home/test/anaconda3/envs/FRL_test/lib/python3.10/site-packages/wandb/sdk/wandb_config.py", line 130, in __getitem__
    return self._items[key]
KeyError: 'af'
The above exception was the direct cause of the following exception:
Traceback (most recent call last):
  File "/home/test/FRL/main.py", line 2, in <module>
    from args import args
  File "/home/test/FRL/args.py", line 179, in <module>
    run_args()
  File "/home/test/FRL/args.py", line 176, in run_args
    args = parse_arguments()
  File "/home/test/FRL/args.py", line 26, in parse_arguments
    af = wandb.config.af
  File "/home/test/anaconda3/envs/FRL_test/lib/python3.10/site-packages/wandb/sdk/wandb_config.py", line 164, in __getattr__
    raise AttributeError(
AttributeError: <class 'wandb.sdk.wandb_config.Config'> object has no attribute 'af'